Workbook

Sheet Metadata
A1: Considerations
A2: The CESs were assigned based on the definition given in the papers analyzed. In cases where no clear definition was given but it was mentioned that a model known as INVEST was used, the INVEST definition was used. In other cases, the tags used in each paper to assign a particular CES were used as a guide for our definition.
A3: In cases where we considered that based on the definition, the CESs should be divided into independent categories, we identified them with an asterisk (*).

Sheet Validacion CES
A1: ID | B1: Title | C1: DOI | D1: DOI link | E1: original CES | F1: CES | G1: IPBES categories | H1: Codigo IPBES | I1: Definition | J1: well defined
A2: 44 | B2: The use of crowdsourced geographic information for spatial evaluation of cultural ecosystem services in the agricultural landscape the case of Chianti Classico (Italy) | C2: 10.30682/nm1902g | D2: =HYPERLINK("https://doi.org/" & C2, C2) -> 10.30682/nm1902g | E2: CESs provided by viticultural landscapes | F2: Enjoy the landscape | G2: =VLOOKUP(F2, Pasarela!$A$1:$F$548, 5, FALSE) -> Physical and psychological experiences | H2: =VLOOKUP(G2, Pasarela!$E$2:$F$548, 2, FALSE) -> 16 | I2: Centered on aesthetic appreciation of a protected area or natural landscape. The photos selected containing the tags “wine”, “vineyard”, “Chianti”, and related words, were filtered | J2: yes
A3: 40 | B3: Social media and deep learning reveal specific cultural preferences for biodiversity | C3: 10.1002/pan3.10466 | D3: =HYPERLINK("https://doi.org/" & C3, C3) -> 10.1002/pan3.10466 | E3: Cultural preferences for biodiversity | F3: Enjoy the fauna and flora | G3: =VLOOKUP(F3, Pasarela!$A$1:$F$548, 5, FALSE) -> Physical and psychological experiences | H3: =VLOOKUP(G3, Pasarela!$E$2:$F$548, 2, FALSE) -> 16 | I3: We define a human interaction -species as an image that represents an individual species as its main theme and we greatly conceptualize these interactions as a cultural service related to the cognitive enjoyment of biodiversity. Based on a list of images of 36 species of birds available in Inaturalist, insects, plants, mammals, reptiles, fungi and others | J3: yes
A4: 36 | B4: Scale dependency in drivers of outdoor recreation in England | C4: 10.1002/pan3.10042 | D4: =HYPERLINK("https://doi.org/" & C4, C4) -> 10.1002/pan3.10042 | E4: Outdoor recreation | F4: Recreation | G4: =VLOOKUP(F4, Pasarela!$A$1:$F$548, 5, FALSE) -> Physical and psychological experiences | H4: =VLOOKUP(G4, Pasarela!$E$2:$F$548, 2, FALSE) -> 16 | I4: Opportunities for outdoor recreation in England range from the use of local green spaces by walkers, dog walkers, community gardeners and families (day-to-day recreation) to planned trips to coastal areas and protected landscapes by hikers, mountain bikers, climbers and other tourists (destination recreation) | J4: yes
A5: 24 | B5: Harnessing artificial intelligence technology and social media data to support Cultural Ecosystem Service assessments | C5: 10.1002/pan3.10199 | D5: =HYPERLINK("https://doi.org/" & C5, C5) -> 10.1002/pan3.10199 | E5: Aesthetic value | F5: Enjoy the landscape | G5: =VLOOKUP(F5, Pasarela!$A$1:$F$548, 5, FALSE) -> Physical and psychological experiences | H5: =VLOOKUP(G5, Pasarela!$E$2:$F$548, 2, FALSE) -> 16 | I5: The definition is not exact but it says the following: For this work, we selected four CESs that are important for the UNESCO world heritage status and that are sensitive to the different pressures exerted by human use in the area, namely aesthetic value, outdoor recreation, cultural heritage and symbolic species (Locatelli et al., 2017) | J5: yes
A6: 24 | B6: Harnessing artificial intelligence technology and social media data to support Cultural Ecosystem Service assessments | C6: 10.1002/pan3.10199 | D6: =HYPERLINK("https://doi.org/" & C6, C6) -> 10.1002/pan3.10199 | E6: Outdoor recreation | F6: Recreation | G6: =VLOOKUP(F6, Pasarela!$A$1:$F$548, 5, FALSE) -> Physical and psychological experiences | H6: =VLOOKUP(G6, Pasarela!$E$2:$F$548, 2, FALSE) -> 16 | I6: The definition is not exact but it says the following: For this work, we selected four CESs that are important for the UNESCO world heritage status and that are sensitive to the different pressures exerted by human use in the area, namely aesthetic value, outdoor recreation, cultural heritage and symbolic species (Locatelli et al., 2017) | J6: yes
A7: 24 | B7: Harnessing artificial intelligence technology and social media data to support Cultural Ecosystem Service assessments | C7: 10.1002/pan3.10199 | D7: =HYPERLINK("https://doi.org/" & C7, C7) -> 10.1002/pan3.10199 | E7: Symbolic species | F7: Enjoy the fauna and flora | G7: =VLOOKUP(F7, Pasarela!$A$1:$F$548, 5, FALSE) -> Physical and psychological experiences | H7: =VLOOKUP(G7, Pasarela!$E$2:$F$548, 2, FALSE) -> 16 | I7: The definition is not exact but it says the following: For this work, we selected four CESs that are important for the UNESCO world heritage status and that are sensitive to the different pressures exerted by human use in the area, namely aesthetic value, outdoor recreation, cultural heritage and symbolic species (Locatelli et al., 2017) | J7: yes
A8: 24 | B8: Harnessing artificial intelligence technology and social media data to support Cultural Ecosystem Service assessments | C8: 10.1002/pan3.10199 | D8: =HYPERLINK("https://doi.org/" & C8, C8) -> 10.1002/pan3.10199 | E8: Cultural heritage | F8: Cultural heritage | G8: =VLOOKUP(F8, Pasarela!$A$1:$F$548, 5, FALSE) -> Supporting identities | H8: =VLOOKUP(G8, Pasarela!$E$2:$F$548, 2, FALSE) -> 17 | I8: The definition is not exact but it says the following: For this work, we selected four CESs that are important for the UNESCO world heritage status and that are sensitive to the different pressures exerted by human use in the area, namely aesthetic value, outdoor recreation, cultural heritage and symbolic species (Locatelli et al., 2017) | J8: yes
A9: 33 | B9: Quantifying wildlife watchers' preferences to investigate the overlap between recreational and conservation value of natural areas | C9: 10.1111/1365-2664.13274 | D9: =HYPERLINK("https://doi.org/" & C9, C9) -> 10.1111/1365-2664.13274 | E9: Recreation | F9: Recreation | G9: =VLOOKUP(F9, Pasarela!$A$1:$F$548, 5, FALSE) -> Physical and psychological experiences | H9: =VLOOKUP(G9, Pasarela!$E$2:$F$548, 2, FALSE) -> 16 | I9: Nature-based recreation substantially benefits human wellbeing, for example, by improving physical and mental health. | J9: yes
A10: 10 | B10: Characterizing nature-based recreation preferences in a Mediterranean small island environment using crowdsourced data | C10: 10.1080/26395916.2023.2274594 | D10: =HYPERLINK("https://doi.org/" & C10, C10) -> 10.1080/26395916.2023.2274594 | E10: people's nature-based recreation | F10: Recreation | G10: =VLOOKUP(F10, Pasarela!$A$1:$F$548, 5, FALSE) -> Physical and psychological experiences | H10: =VLOOKUP(G10, Pasarela!$E$2:$F$548, 2, FALSE) -> 16 | I10: The definition is not exact but it says the following: Labels defining nature-based recreation (i.e. diving, hiking or people recreating in nature) were used to categorize images depicting nature-based recreational activities | J10: yes
A11: 49 | B11: Using social media data and machine learning to map recreational ecosystem services | C11: 10.1016/j.ecolind.2023.110606 | D11: =HYPERLINK("https://doi.org/" & C11, C11) -> 10.1016/j.ecolind.2023.110606 | E11: Recreation | F11: Recreation | G11: =VLOOKUP(F11, Pasarela!$A$1:$F$548, 5, FALSE) -> Physical and psychological experiences | H11: =VLOOKUP(G11, Pasarela!$E$2:$F$548, 2, FALSE) -> 16 | I11: Recreation measured from geotagged photographs posted to Flickr based on the locations of natural habitats and other features that factor into people’s decisions about where to recreate. Our analysis focuses on nature-based recreation, i.e., recreational activities involving physical and experiential interactions with the natural environment. We manually categorized all labels and classified them into ten categories that depict: 1) trees; 2) other vegetation types; 3) accessibility; 4) wildlife; 5) rocks, hills, and mountains; 6) water; 7) recreational activities; 8) accommodation; 9) general landscape features; and 10) attractions | J11: yes
A12: 15 | B12: Cultural ecosystem services provided by rivers across diverse social-ecological landscapes: A social media analysis | C12: 10.1016/j.ecolind.2019.105580 | D12: =HYPERLINK("https://doi.org/" & C12, C12) -> 10.1016/j.ecolind.2019.105580 | E12: Aesthetics | F12: Enjoy the landscape | G12: =VLOOKUP(F12, Pasarela!$A$1:$F$548, 5, FALSE) -> Physical and psychological experiences | H12: =VLOOKUP(G12, Pasarela!$E$2:$F$548, 2, FALSE) -> 16 | I12: The definition is not exact but these are the key words to define the CES: view, scene, sunset, wonder, abandon | J12: yes
A13: 15 | B13: Cultural ecosystem services provided by rivers across diverse social-ecological landscapes: A social media analysis | C13: 10.1016/j.ecolind.2019.105580 | D13: =HYPERLINK("https://doi.org/" & C13, C13) -> 10.1016/j.ecolind.2019.105580 | E13: Cultural diversity | F13: Cultural heritage | G13: =VLOOKUP(F13, Pasarela!$A$1:$F$548, 5, FALSE) -> Supporting identities | H13: =VLOOKUP(G13, Pasarela!$E$2:$F$548, 2, FALSE) -> 17 | I13: The definition is not exact but these are the key words to define the CES: people, museum, indian, culture, river | J13: yes
... A17: 15 | B17: Cultural ecosystem services provided by rivers across diverse social-ecological landscapes: A social media analysis | C17: 10.1016/j.ecolind.2019.105580 | D17: =HYPERLINK("https://doi.org/" & C17, C17) -> 10.1016/j.ecolind.2019.105580 | E17: Inspiration* | F17: Psychological experiences | G17: =VLOOKUP(F17, Pasarela!$A$1:$F$548, 5, FALSE) -> Physical and psychological experiences | H17: =VLOOKUP(G17, Pasarela!$E$2:$F$548, 2, FALSE) -> 16 | I17: The definition is not exact but these are the key words to define the CES: memory, love, think, art, wonder | J17: no
A18: 15 | B18: Cultural ecosystem services provided by rivers across diverse social-ecological landscapes: A social media analysis | C18: 10.1016/j.ecolind.2019.105580 | D18: =HYPERLINK("https://doi.org/" & C18, C18) -> 10.1016/j.ecolind.2019.105580 | E18: Inspiration* | F18: Artistic inspiration | G18: Learning and inspiration | H18: =VLOOKUP(G18, Pasarela!$E$2:$F$548, 2, FALSE) -> 15 | I18: The definition is not exact but these are the key words to define the CES: memory, love, think, art, wonder | J18: no
A19: 15 | B19: Cultural ecosystem services provided by rivers across diverse social-ecological landscapes: A social media analysis | C19: 10.1016/j.ecolind.2019.105580 | D19: =HYPERLINK("https://doi.org/" & C19, C19) -> 10.1016/j.ecolind.2019.105580 | E19: Knowledge systems | F19: Research | G19: =VLOOKUP(F19, Pasarela!$A$1:$F$548, 5, FALSE) -> Learning and inspiration | H19: =VLOOKUP(G19, Pasarela!$E$2:$F$548, 2, FALSE) -> 15 | I19: The definition is not exact but these are the key words to define the CES: PlantParts, think, native, museum, discover | J19: yes
A20: 15 | B20: Cultural ecosystem services provided by rivers across diverse social-ecological landscapes: A social media analysis | C20: 10.1016/j.ecolind.2019.105580 | D20: =HYPERLINK("https://doi.org/" & C20, C20) -> 10.1016/j.ecolind.2019.105580 | E20: Recreation | F20: Recreation | G20: =VLOOKUP(F20, Pasarela!$A$1:$F$548, 5, FALSE) -> Physical and psychological experiences | H20: =VLOOKUP(G20, Pasarela!$E$2:$F$548, 2, FALSE) -> 16 | I20: The definition is not exact but these are the key words to define the CES: travel, boating, camping, raft, cycle | J20: yes
A21: 15 | B21: Cultural ecosystem services provided by rivers across diverse social-ecological landscapes: A social media analysis | C21: 10.1016/j.ecolind.2019.105580 | D21: =HYPERLINK("https://doi.org/" & C21, C21) -> 10.1016/j.ecolind.2019.105580 | E21: Sense of place | F21: Cultural heritage | G21: =VLOOKUP(F21, Pasarela!$A$1:$F$548, 5, FALSE) -> Supporting identities | H21: =VLOOKUP(G21, Pasarela!$E$2:$F$548, 2, FALSE) -> 17 | I21: The definition is not exact but these are the key words to define the CES: abandon, historic, connect, Culture, folk | J21: yes
A22: 15 | B22: Cultural ecosystem services provided by rivers across diverse social-ecological landscapes: A social media analysis | C22: 10.1016/j.ecolind.2019.105580 | D22: =HYPERLINK("https://doi.org/" & C22, C22) -> 10.1016/j.ecolind.2019.105580 | E22: Social relations | F22: Social relations | G22: Supporting identities | H22: =VLOOKUP(G22, Pasarela!$E$2:$F$548, 2, FALSE) -> 17 | I22: The definition is not exact but these are the key words to define the CES: wedding, family, celebrate, memory, love | J22: yes
A23: 15 | B23: Cultural ecosystem services provided by rivers across diverse social-ecological landscapes: A social media analysis | C23: 10.1016/j.ecolind.2019.105580 | D23: =HYPERLINK("https://doi.org/" & C23, C23) -> 10.1016/j.ecolind.2019.105580 | E23: Spiritual | F23: Spiritual significance | G23: =VLOOKUP(F23, Pasarela!$A$1:$F$548, 5, FALSE) -> Supporting identities | H23: =VLOOKUP(G23, Pasarela!$E$2:$F$548, 2, FALSE) -> 17 | I23: The definition is not exact but these are the key words to define the CES: celebrate, memory, love, mission, reflect | J23: yes
A24: 13 | B24: Crowdsourcing indicators for cultural ecosystem services: A geographically weighted approach for mountain landscapes | C24: 10.1016/j.ecolind.2015.12.042 | D24: =HYPERLINK("https://doi.org/" & C24, C24) -> 10.1016/j.ecolind.2015.12.042 | E24: Physical and experiential interactions* | F24: Enjoy the fauna and flora | G24: =VLOOKUP(F24, Pasarela!$A$1:$F$548, 5, FALSE) -> Physical and psychological experiences | H24: =VLOOKUP(G24, Pasarela!$E$2:$F$548, 2, FALSE) -> 16 | I24: Experiential use and enjoyment of wildlife – represented by photographs of wildlife | J24: no
A25: 13 | B25: Crowdsourcing indicators for cultural ecosystem services: A geographically weighted approach for mountain landscapes | C25: 10.1016/j.ecolind.2015.12.042 | D25: =HYPERLINK("https://doi.org/" & C25, C25) -> 10.1016/j.ecolind.2015.12.042 | E25: Physical and experiential interactions* | F25: Enjoy the landscape | G25: =VLOOKUP(F25, Pasarela!$A$1:$F$548, 5, FALSE) -> Physical and psychological experiences | H25: =VLOOKUP(G25, Pasarela!$E$2:$F$548, 2, FALSE) -> 16 | I25: Physical use of landscapes | J25: no
A26: 13 | B26: Crowdsourcing indicators for cultural ecosystem services: A geographically weighted approach for mountain landscapes | C26: 10.1016/j.ecolind.2015.12.042 | D26: =HYPERLINK("https://doi.org/" & C26, C26) -> 10.1016/j.ecolind.2015.12.042 | E26: Physical and experiential interactions* | F26: Recreation | G26: =VLOOKUP(F26, Pasarela!$A$1:$F$548, 5, FALSE) -> Physical and psychological experiences | H26: =VLOOKUP(G26, Pasarela!$E$2:$F$548, 2, FALSE) -> 16 | I26: Photographs of sport and recreational activities, such as skiing, climbing, hiking, camping and others. | J26: no
A27: 13 | B27: Crowdsourcing indicators for cultural ecosystem services: A geographically weighted approach for mountain landscapes | C27: 10.1016/j.ecolind.2015.12.042 | D27: =HYPERLINK("https://doi.org/" & C27, C27) -> 10.1016/j.ecolind.2015.12.042 | E27: Intellectual and representative interactions* | F27: Environmental education | G27: =VLOOKUP(F27, Pasarela!$A$1:$F$548, 5, FALSE) -> Learning and inspiration | H27: =VLOOKUP(G27, Pasarela!$E$2:$F$548, 2, FALSE) -> 15 | I27: Educational activities – represented by photographs of groups of students undertaking nature-related activities | J27: no
A28: 13 | B28: Crowdsourcing indicators for cultural ecosystem services: A geographically weighted approach for mountain landscapes | C28: 10.1016/j.ecolind.2015.12.042 | D28: =HYPERLINK("https://doi.org/" & C28, C28) -> 10.1016/j.ecolind.2015.12.042 | E28: Intellectual and representative interactions* | F28: Enjoy the landscape | G28: =VLOOKUP(F28, Pasarela!$A$1:$F$548, 5, FALSE) -> Physical and psychological experiences | H28: =VLOOKUP(G28, Pasarela!$E$2:$F$548, 2, FALSE) -> 16 | I28: Landscape aesthetics – photographs of natural and anthropic landscapes | J28: no
A29: 13 | B29: Crowdsourcing indicators for cultural ecosystem services: A geographically weighted approach for mountain landscapes | C29: 10.1016/j.ecolind.2015.12.042 | D29: =HYPERLINK("https://doi.org/" & C29, C29) -> 10.1016/j.ecolind.2015.12.042 | E29: Intellectual and representative interactions* | F29: Cultural heritage | G29: =VLOOKUP(F29, Pasarela!$A$1:$F$548, 5, FALSE) -> Supporting identities | H29: =VLOOKUP(G29, Pasarela!$E$2:$F$548, 2, FALSE) -> 17 | I29: Cultural heritage – representation of traditional livestock feeding practices and lifestyle related to agricultural heritage | J29: no
A30: 12 | B30: Combining social media photographs and species distribution models to map cultural ecosystem services: The case of a Natural Park in Portugal | C30: 10.1016/j.ecolind.2018.08.043 | D30: =HYPERLINK("https://doi.org/" & C30, C30) -> 10.1016/j.ecolind.2018.08.043 | E30: Cultural heritage and identity | F30: Cultural heritage | G30: =VLOOKUP(F30, Pasarela!$A$1:$F$548, 5, FALSE) -> Supporting identities | H30: =VLOOKUP(G30, Pasarela!$E$2:$F$548, 2, FALSE) -> 17 | I30: Value of landscapes, ecosystems, species or sites for local heritage and culture (including tangible and intangible heritage). | J30: yes
A31: 12 | B31: Combining social media photographs and species distribution models to map cultural ecosystem services: The case of a Natural Park in Portugal | C31: 10.1016/j.ecolind.2018.08.043 | D31: =HYPERLINK("https://doi.org/" & C31, C31) -> 10.1016/j.ecolind.2018.08.043 | E31: Inspiration | F31: Psychological experiences | G31: =VLOOKUP(F31, Pasarela!$A$1:$F$548, 5, FALSE) -> Physical and psychological experiences | H31: =VLOOKUP(G31, Pasarela!$E$2:$F$548, 2, FALSE) -> 16 | I31: Use of landscapes, ecosystems and their elements in arts, architecture, advertising, local symbols, folklore, etc | J31: yes
A32: 12 | B32: Combining social media photographs and species distribution models to map cultural ecosystem services: The case of a Natural Park in Portugal | C32: 10.1016/j.ecolind.2018.08.043 | D32: =HYPERLINK("https://doi.org/" & C32, C32) -> 10.1016/j.ecolind.2018.08.043 | E32: Inspiration* | F32: Artistic inspiration | G32: Learning and inspiration | H32: =VLOOKUP(G32, Pasarela!$E$2:$F$548, 2, FALSE) -> 15 | I32: Use of landscapes, ecosystems and their elements in arts, architecture, advertising, local symbols, folklore, etc | J32: no
A33: 12 | B33: Combining social media photographs and species distribution models to map cultural ecosystem services: The case of a Natural Park in Portugal | C33: 10.1016/j.ecolind.2018.08.043 | D33: =HYPERLINK("https://doi.org/" & C33, C33) -> 10.1016/j.ecolind.2018.08.043 | E33: Recreation | F33: Recreation | G33: =VLOOKUP(F33, Pasarela!$A$1:$F$548, 5, FALSE) -> Physical and psychological experiences | H33: =VLOOKUP(G33, Pasarela!$E$2:$F$548, 2, FALSE) -> 16 | I33: Opportunities provided by ecosystems (their biotic and abiotic elements) for recreational activities. | J33: yes
A34: 12 | B34: Combining social media photographs and species distribution models to map cultural ecosystem services: The case of a Natural Park in Portugal | C34: 10.1016/j.ecolind.2018.08.043 | D34: =HYPERLINK("https://doi.org/" & C34, C34) -> 10.1016/j.ecolind.2018.08.043 | E34: Scientific and educational* | F34: Research | G34: =VLOOKUP(F34, Pasarela!$A$1:$F$548, 5, FALSE) -> Learning and inspiration | H34: =VLOOKUP(G34, Pasarela!$E$2:$F$548, 2, FALSE) -> 15 | I34: Research or educational activities conducted through the natural environment of the ecosystem and its biological and non-biological components. Examples: Comments containing attractions for educational training or research activities, (e.g., educational bases). | J34: no
A35: 12 | B35: Combining social media photographs and species distribution models to map cultural ecosystem services: The case of a Natural Park in Portugal | C35: 10.1016/j.ecolind.2018.08.043 | D35: =HYPERLINK("https://doi.org/" & C35, C35) -> 10.1016/j.ecolind.2018.08.043 | E35: Scientific and educational* | F35: Environmental education | G35: =VLOOKUP(F35, Pasarela!$A$1:$F$548, 5, FALSE) -> Learning and inspiration | H35: =VLOOKUP(G35, Pasarela!$E$2:$F$548, 2, FALSE) -> 15 | I35: Research or educational activities conducted through the natural environment of the ecosystem and its biological and non-biological components. Examples: Comments containing attractions for educational training or research activities, (e.g., educational bases). | J35: no
A36: 12 | B36: Combining social media photographs and species distribution models to map cultural ecosystem services: The case of a Natural Park in Portugal | C36: 10.1016/j.ecolind.2018.08.043 | D36: =HYPERLINK("https://doi.org/" & C36, C36) -> 10.1016/j.ecolind.2018.08.043 | E36: Spiritual and religious | F36: Spiritual significance | G36: =VLOOKUP(F36, Pasarela!$A$1:$F$548, 5, FALSE) -> Supporting identities | H36: =VLOOKUP(G36, Pasarela!$E$2:$F$548, 2, FALSE) -> 17 | I36: Use of landscapes, ecosystems and their elements for religious or spiritual purposes | J36: yes
A37: 21 | B37: Explicit quantification of coastal cultural ecosystem services: A novel approach based on the content and sentimental analysis of social media | C37: 10.1016/j.ecolind.2022.108756 | D37: =HYPERLINK("https://doi.org/" & C37, C37) -> 10.1016/j.ecolind.2022.108756 | E37: Aesthetic | F37: Enjoy the landscape | G37: =VLOOKUP(F37, Pasarela!$A$1:$F$548, 5, FALSE) -> Physical and psychological experiences | H37: =VLOOKUP(G37, Pasarela!$E$2:$F$548, 2, FALSE) -> 16 | I37: Aesthetic services are the combination of the pluralistic attractiveness of nature from the perspective of different civilizations. Coastal ecosystems are composed of various landscape elements, and their appreciation is evaluated from specific landscape elements and overall preferences. | J37: yes
A38: 21 | B38: Explicit quantification of coastal cultural ecosystem services: A novel approach based on the content and sentimental analysis of social media | C38: 10.1016/j.ecolind.2022.108756 | D38: =HYPERLINK("https://doi.org/" & C38, C38) -> 10.1016/j.ecolind.2022.108756 | E38: Amenity | F38: Recreation | G38: =VLOOKUP(F38, Pasarela!$A$1:$F$548, 5, FALSE) -> Physical and psychological experiences | H38: =VLOOKUP(G38, Pasarela!$E$2:$F$548, 2, FALSE) -> 16 | I38: Amenity services represent the impact of natural components on human communities (Cochrane, 2006). A comfortable environment is visible and unique for both visitors and residents with reliable infrastructures in coastal attractions | J38: yes
A39: 21 | B39: Explicit quantification of coastal cultural ecosystem services: A novel approach based on the content and sentimental analysis of social media | C39: 10.1016/j.ecolind.2022.108756 | D39: =HYPERLINK("https://doi.org/" & C39, C39) -> 10.1016/j.ecolind.2022.108756 | E39: Knowledge* | F39: Environmental education | G39: =VLOOKUP(F39, Pasarela!$A$1:$F$548, 5, FALSE) -> Learning and inspiration | H39: =VLOOKUP(G39, Pasarela!$E$2:$F$548, 2, FALSE) -> 15 | I39: From indigenous knowledge systems to modern science, knowledge of the ecological environment is essential for the sustainable use of natural resources, climate change adaptation, and ecosystem resilience (Díaz et al., 2018, Haines-Young and Potschin-Young, 2018). The coastal ecosystem provides a material basis for scientific research and education. For example, coastal and oceanic observatories offer services for delivering high-quality environmental data to meet societal and political needs (El Serafy, 2020). Such an ecosystem enables people to draw on relevant knowledge identified as knowledge services. Recently, social media propagation has raised public awareness of the natural environment witnessed by both celebrities and ordinary people (Richards and Friess, 2015). | J39: no
A40: 21 | B40: Explicit quantification of coastal cultural ecosystem services: A novel approach based on the content and sentimental analysis of social media | C40: 10.1016/j.ecolind.2022.108756 | D40: =HYPERLINK("https://doi.org/" & C40, C40) -> 10.1016/j.ecolind.2022.108756 | E40: Knowledge* | F40: Research | G40: =VLOOKUP(F40, Pasarela!$A$1:$F$548, 5, FALSE) -> Learning and inspiration | H40: =VLOOKUP(G40, Pasarela!$E$2:$F$548, 2, FALSE) -> 15 | I40: From indigenous knowledge systems to modern science, knowledge of the ecological environment is essential for the sustainable use of natural resources, climate change adaptation, and ecosystem resilience (Díaz et al., 2018, Haines-Young and Potschin-Young, 2018). The coastal ecosystem provides a material basis for scientific research and education. For example, coastal and oceanic observatories offer services for delivering high-quality environmental data to meet societal and political needs (El Serafy, 2020). Such an ecosystem enables people to draw on relevant knowledge identified as knowledge services. Recently, social media propagation has raised public awareness of the natural environment witnessed by both celebrities and ordinary people (Richards and Friess, 2015). | J40: no
A41: 21 | B41: Explicit quantification of coastal cultural ecosystem services: A novel approach based on the content and sentimental analysis of social media | C41: 10.1016/j.ecolind.2022.108756 | D41: =HYPERLINK("https://doi.org/" & C41, C41) -> 10.1016/j.ecolind.2022.108756 | E41: Naturalistic | F41: Enjoy the fauna and flora | G41: =VLOOKUP(F41, Pasarela!$A$1:$F$548, 5, FALSE) -> Physical and psychological experiences | H41: =VLOOKUP(G41, Pasarela!$E$2:$F$548, 2, FALSE) -> 16 | I41: Proenvironmental attitudes and behaviors and consciousness of mediating a proper relationship between all living organisms on Earth (Katz-Gerro and Orenstein, 2015) inspire people to pursue a greater sense of spiritual well-being. Notably, the coastal biome is one of the habitats with the greatest diversity of species in the world (Wolanski and McLusky, 2011). However, unique biomes such as mangroves and wetlands near coastal cities are threatened by extensive reclamation projects, depleting fish stocks, and coastal waters tainted by domestic waste and pollutants (Friess, 2017, Garcia Rodrigues et al., 2017). Thus, an assessment of naturalistic services is a preliminary practice for developing sustainable coastal tourism. | J41: yes
A42: 21 | B42: Explicit quantification of coastal cultural ecosystem services: A novel approach based on the content and sentimental analysis of social media | C42: 10.1016/j.ecolind.2022.108756 | D42: =HYPERLINK("https://doi.org/" & C42, C42) -> 10.1016/j.ecolind.2022.108756 | E42: Recreational | F42: Recreation | G42: =VLOOKUP(F42, Pasarela!$A$1:$F$548, 5, FALSE) -> Physical and psychological experiences | H42: =VLOOKUP(G42, Pasarela!$E$2:$F$548, 2, FALSE) -> 16 | I42: Recreational services represent the cultural benefits arising from sports-related activities, which include land and water recreation (Jackson et al., 2013, Balzan and Debono, 2018, Havinga et al., 2020). Many outdoor recreational activities in coastal areas are dependent on the availability and distribution of ecosystems, including those for jogging, cycling, and sailing. Recreational services benefit people's health and well-being by providing a pleasant physical environment. | J42: yes
A43: 21 | B43: Explicit quantification of coastal cultural ecosystem services: A novel approach based on the content and sentimental analysis of social media | C43: 10.1016/j.ecolind.2022.108756 | D43: =HYPERLINK("https://doi.org/" & C43, C43) -> 10.1016/j.ecolind.2022.108756 | E43: Spiritual and religious* | F43: Spiritual significance | G43: =VLOOKUP(F43, Pasarela!$A$1:$F$548, 5, FALSE) -> Supporting identities | H43: =VLOOKUP(G43, Pasarela!$E$2:$F$548, 2, FALSE) -> 17 | I43: A sacred landscape in the wild is central to religious tourism or secular pilgrimage, arousing beliefs of the past and promoting a heritage of cultural memory (Hernández-Morcillo et al., 2013, Clemente et al., 2019). In residing in a coastal environment for centuries, communities with racial and ethnic differences have particular cultures of entertainment, recreation, social customs, and habits that shape religious beliefs and essential elements of their lives. | J43: no
...

Sheet Pasarela
A1: NCP simple | B1: NCP | C1: Description (IPBES) | D1: Definition CES Diaz et al. | E1: Name | F1: Code
A2: Sense of belonging | B2: Sense of belonging (e.g. rootedness or connection) | C2: Landscapes, seascapes, habitats or organisms being the basis for religious, spiritual, and social-cohesion experiences: • Provisioning of opportunities by nature for people to develop a sense of place, belonging, rootedness or connectedness, associated with different entities of the living world (e. g. cultural, sacred and heritage landscapes, sounds, scents and sights associated with childhood experiences, iconic animals, trees or flowers) (187-198) • Basis for narratives, rituals and celebrations provided by landscapes, seascapes, habitats, species or organisms (13, 21, 169, 188, 189, 191, 199) • Source of satisfaction derived from knowing that a particular landscape, seascape, habitat or species exists (200, 201) | D2: Landscapes, seascapes, habitats or organisms being the basis for religious, spiritual, and social-cohesion experiences: • Provisioning of opportunities by nature for people to develop a sense of place, belonging, rootedness or connectedness, associated with different entities of the living world (e. g. cultural, sacred and heritage landscapes, sounds, scents and sights associated with childhood experiences, iconic animals, trees or flowers) (187-198) • Basis for narratives, rituals and celebrations provided by landscapes, seascapes, habitats, species or organisms (13, 21, 169, 188, 189, 191, 199) • Source of satisfaction derived from knowing that a particular landscape, seascape, habitat or species exists (200, 201) | E2: Supporting identities | F2: 17
A3: Environmental education | B3: Environmental education (e.g. places used for conservation activities) | C3: Learning and inspiration: Capabilities developed through education, knowledge acquisition, and inspiration by nature for art and technological design | D3: Provision, by landscapes, seascapes, habitats or organisms, of opportunities for the development of the capabilities that allow humans to prosper through education, acquisition of knowledge and development of skills for well-being, information, and inspiration for art and technological design (e.g. biomimicry) (165-174) | E3: Learning and inspiration | F3: 15
A4: Enjoy the fauna and flora | B4: Enjoy the fauna and flora (e.g. photography of emblematic species) | C4: Physical and psychological experiences: Physically and psychologically beneficial activities, healing, relaxation, recreation, and aesthetic enjoyment based on contact with nature | D4: Provision, by landscapes, seascapes, habitats or organisms, of opportunities for physically and psychologically beneficial activities, healing, relaxation, recreation, leisure, tourism and aesthetic enjoyment based on the close contact with nature (e.g. hiking, recreational hunting and fishing, birdwatching, snorkeling, diving, gardening) (175-187) | E4: Physical and psychological experiences | F4: 16
A5: Cultural heritage | B5: Cultural heritage (e.g. historical objects or landscape and/or intangible aspects) | C5: Supporting identities: The basis for religious, spiritual, and social cohesion; sense of place, purpose, belonging, or rootedness associated with the living world; narratives, myths, and rituals; satisfaction from a landscape, seascape, habitat, or species | D5: Landscapes, seascapes, habitats or organisms being the basis for religious, spiritual, and social-cohesion experiences: • Provisioning of opportunities by nature for people to develop a sense of place, belonging, rootedness or connectedness, associated with different entities of the living world (e. g. cultural, sacred and heritage landscapes, sounds, scents and sights associated with childhood experiences, iconic animals, trees or flowers) (187-198) • Basis for narratives, rituals and celebrations provided by landscapes, seascapes, habitats, species or organisms (13, 21, 169, 188, 189, 191, 199) • Source of satisfaction derived from knowing that a particular landscape, seascape, habitat or species exists (200, 201) | E5: Supporting identities | F5: 17
A6: Recreation (e.g. hunting, fishing) | B6: Recreation (e.g. hunting, fishing) | C6: Physical and psychological experiences: Physically and psychologically beneficial activities, healing, relaxation, recreation, and aesthetic enjoyment based on contact with nature | D6: Provision, by landscapes, seascapes, habitats or organisms, of opportunities for physically and psychologically beneficial activities, healing, relaxation, recreation, leisure, tourism and aesthetic enjoyment based on the close contact with nature (e.g. hiking, recreational hunting and fishing, birdwatching, snorkeling, diving, gardening) (175-187) | E6: Physical and psychological experiences | F6: 16
A7: Recreation | B7: Recreation (e.g. bird watching, ecotourism, hiking, skiing, biking, horseback riding) | C7: Physical and psychological experiences: Physically and psychologically beneficial activities, healing, relaxation, recreation, and aesthetic enjoyment based on contact with nature | D7: Provision, by landscapes, seascapes, habitats or organisms, of opportunities for physically and psychologically beneficial activities, healing, relaxation, recreation, leisure, tourism and aesthetic enjoyment based on the close contact with nature (e.g. hiking, recreational hunting and fishing, birdwatching, snorkeling, diving, gardening) (175-187) | E7: Physical and psychological experiences | F7: 16
A8: Psychological experiences | B8: Psychological experiences (e.g. relaxation, peace of mind) | C8: Physical and psychological experiences: Physically and psychologically beneficial activities, healing, relaxation, recreation, and aesthetic enjoyment based on contact with nature | D8: Provision, by landscapes, seascapes, habitats or organisms, of opportunities for physically and psychologically beneficial activities, healing, relaxation, recreation, leisure, tourism and aesthetic enjoyment based on the close contact with nature (e.g. hiking, recreational hunting and fishing, birdwatching, snorkeling, diving, gardening) (175-187) | E8: Physical and psychological experiences | F8: 16
A9: Research | B9: Research (e.g. places of special scientific interest) | C9: Learning and inspiration: Capabilities developed through education, knowledge acquisition, and inspiration by nature for art and technological design | D9: Provision, by landscapes, seascapes, habitats or organisms, of opportunities for the development of the capabilities that allow humans to prosper through education, acquisition of knowledge and development of skills for well-being, information, and inspiration for art and technological design (e.g. biomimicry) (165-174) | E9: Learning and inspiration | F9: 15
A10: Enjoy the landscape | B10: Enjoy the landscape (e.g. its beauty) | C10: Physical and psychological experiences: Physically and psychologically beneficial activities, healing, relaxation, recreation, and aesthetic enjoyment based on contact with nature | D10: Provision, by landscapes, seascapes, habitats or organisms, of opportunities for physically and psychologically beneficial activities, healing, relaxation, recreation, leisure, tourism and aesthetic enjoyment based on the close contact with nature (e.g. hiking, recreational hunting and fishing, birdwatching, snorkeling, diving, gardening) (175-187) | E10: Physical and psychological experiences | F10: 16
A11: Spiritual significance | B11: Spiritual significance (eg spiritual and/or religious enrichment) | C11: Supporting identities: The basis for religious, spiritual, and social cohesion; sense of place, purpose, belonging, or rootedness associated with the living world; narratives, myths, and rituals; satisfaction from a landscape, seascape, habitat, or species | D11: Landscapes, seascapes, habitats or organisms being the basis for religious, spiritual, and social-cohesion experiences: • Provisioning of opportunities by nature for people to develop a sense of place, belonging, rootedness or connectedness, associated with different entities of the living world (e. g. cultural, sacred and heritage landscapes, sounds, scents and sights associated with childhood experiences, iconic animals, trees or flowers) (187-198) • Basis for narratives, rituals and celebrations provided by landscapes, seascapes, habitats, species or organisms (13, 21, 169, 188, 189, 191, 199) • Source of satisfaction derived from knowing that a particular landscape, seascape, habitat or species exists (200, 201) | E11: Supporting identities | F11: 17
A12: Rural tourism | B12: Rural tourism (e.g. visits and/or walks through a town) | C12: Supporting identities: The basis for religious, spiritual, and social cohesion; sense of place, purpose, belonging, or rootedness associated with the living world; narratives, myths, and rituals; satisfaction from a landscape, seascape, habitat, or species | D12: Landscapes, seascapes, habitats or organisms being the basis for religious, spiritual, and social-cohesion experiences: • Provisioning of opportunities by nature for people to develop a sense of place, belonging, rootedness or connectedness, associated with different entities of the living world (e. g. cultural, sacred and heritage landscapes, sounds, scents and sights associated with childhood experiences, iconic animals, trees or flowers) (187-198) • Basis for narratives, rituals and celebrations provided by landscapes, seascapes, habitats, species or organisms (13, 21, 169, 188, 189, 191, 199) • Source of satisfaction derived from knowing that a particular landscape, seascape, habitat or species exists (200, 201) | E12: Supporting identities | F12: 17
A13: Maintenance of options | B13: Maintenance of options | C13: Capacity of ecosystems, habitats, species or genotypes to keep options open in order to support a good quality of life. | D13: Capacity of ecosystems, habitats, species or genotypes to keep options open in order to support a good quality of life. Examples include: • Benefits (including those of future generations) associated with the continued existence of a wide variety of species, populations and genotypes. This includes their contributions to the resilience and resistance of ecosystem properties in the face of environmental change and variability (6, 7, 203-206) • Future benefits (or threats) derived from keeping options open for yet unknown discoveries and unanticipated uses of particular organisms or ecosystems that already exist (e.g. new medicines or materials) (5) • Future benefits (or threats) that may be anticipated from on- going biological evolution (e.g. adaptation to a warmer climate, to emergent diseases, development of resistance to antibiotics and other control agents by pathogens and weeds) | E13: Maintenance of options | F13: 18
A14: Intrinsic | B14: Intrinsic | E14: Maintenance of options
A15: Social relations | B15: Social relations | C15: Supporting identities: The basis for religious, spiritual, and social cohesion; sense of place, purpose, belonging, or rootedness associated with the living world; narratives, myths, and rituals; satisfaction from a landscape, seascape, habitat, or species | D15: Landscapes, seascapes, habitats or organisms being the basis for religious, spiritual, and social-cohesion experiences: • Provisioning of opportunities by nature for people to develop a sense of place, belonging, rootedness or connectedness, associated with different entities of the living world (e. g. cultural, sacred and heritage landscapes, sounds, scents and sights associated with childhood experiences, iconic animals, trees or flowers) (187-198) • Basis for narratives, rituals and celebrations provided by landscapes, seascapes, habitats, species or organisms (13, 21, 169, 188, 189, 191, 199) • Source of satisfaction derived from knowing that a particular landscape, seascape, habitat or species exists (200, 201) | E15: Supporting identities | F15: 17
A16: Artistic inspiration | B16: Artistic inspiration | C16: Learning and inspiration: Capabilities developed through education, knowledge acquisition, and inspiration by nature for art and technological design | D16: Provision, by landscapes, seascapes, habitats or organisms, of opportunities for the development of the capabilities that allow humans to prosper through education, acquisition of knowledge and development of skills for well-being, information, and inspiration for art and technological design (e.g. biomimicry) (165-174) | E16: Learning and inspiration | F16: 15
A17: Non-material NCP | B17: Non-material NCP | C17: Includes all | D17: Includes all | E17: Non-material NCP | F17: 15,16,17,18
